Workbook

Sheet Grundmatris Sampers
A2: Grundmatris Sampers 2019 (pb +pby)
C3: 700611 | D3: 700612 | E3: 700613 | F3: 700614 | G3: 700715 | H3: 700716 | I3: 700817 | J3: 700818 | K3: 700819 | L3: 700820 | M3: 701022 | N3: 738101 | O3: 738102 | P3: 738103 | Q3: 738104 | R3: 738105 | S3: 738107 | T3: 738108 | U3: 738109 | V3: 738110 | W3: 738111 | X3: 738112 | Y3: 738151 | Z3: 738152 | AA3: 738153
B4: 700611 | C4: 0 | D4: 0 | E4: 0.733032 | F4: 5.519764 | G4: 1.339761 | H4: 13.100322 | I4: 3.662453 | J4: 1.439829 | K4: 4.319857 | L4: 0.613063 | M4: 0.060561 | N4: 12.050244 | O4: 6.783384 | P4: 1.237538 | Q4: 0.999889 | R4: 2.204737 | S4: 7.521979 | T4: 1.634523 | U4: 0.589768 | V4: 1.145661 | W4: 0.923085 | X4: 2.144383 | Y4: 2.853134 | Z4: 3.621463 | AA4: 4.327176
B5: 700612 | C5: 0 | D5: 0 | E5: 2.193773 | F5: 3.506957 | G5: 1.708081 | H5: 25.612949 | I5: 3.594923 | J5: 2.797354 | K5: 4.35267 | L5: 1.133021 | M5: 0.046015 | N5: 14.496846 | O5: 6.068456 | P5: 1.556159 | Q5: 0.989931 | R5: 5.526294 | S5: 12.050697 | T5: 1.671757 | U5: 1.197285 | V5: 2.583891 | W5: 1.478546 | X5: 5.24642 | Y5: 3.916555 | Z5: 2.604088 | AA5: 5.31917
B6: 700613 | C6: 2.979703 | D6: 1.434597 | E6: 0 | F6: 7.734862 | G6: 3.684088 | H6: 23.219633 | I6: 23.498498 | J6: 14.212009 | K6: 5.310744 | L6: 1.617766 | M6: 0.631449 | N6: 14.82001 | O6: 5.748292 | P6: 1.137481 | Q6: 1.471306 | R6: 4.581621 | S6: 9.685256 | T6: 0.892182 | U6: 1.818511 | V6: 1.062102 | W6: 1.026715 | X6: 2.473409 | Y6: 3.772572 | Z6: 1.653121 | AA6: 4.675579
B7: 700614 | C7: 2.762057 | D7: 4.063984 | E7: 1.391482 | F7: 0 | G7: 16.61195 | H7: 0 | I7: 61.001679 | J7: 56.557619 | K7: 29.108081 | L7: 16.433524 | M7: 1.972008 | N7: 37.849767 | O7: 20.451835 | P7: 1.999168 | Q7: 2.707451 | R7: 8.668517 | S7: 23.459538 | T7: 7.234637 | U7: 4.986668 | V7: 3.65763 | W7: 4.128819 | X7: 9.55214 | Y7: 7.914043 | Z7: 5.273126 | AA7: 16.918924
B8: 700715 | C8: 1.275342 | D8: 1.617101 | E8: 0.765046 | F8: 11.08358 | G8: 0 | H8: 3.724316 | I8: 29.665761 | J8: 9.893036 | K8: 0.52929 | L8: 1.305452 | M8: 0 | N8: 21.740548 | O8: 17.785945 | P8: 1.742754 | Q8: 2.708937 | R8: 4.545305 | S8: 10.938745 | T8: 3.709403 | U8: 2.566212 | V8: 2.006285 | W8: 2.35539 | X8: 4.509239 | Y8: 3.940958 | Z8: 2.787641 | AA8: 5.936065
B9: 700716 | C9: 11.852271 | D9: 10.237136 | E9: 5.731874 | F9: 0 | G9: 1.568403 | H9: 0 | I9: 678.14585 | J9: 179.57556 | K9: 19.979292 | L9: 105.04038 | M9: 0 | N9: 64.593383 | O9: 26.993509 | P9: 6.613115 | Q9: 5.209818 | R9: 20.043822 | S9: 54.874559 | T9: 17.935116 | U9: 7.998388 | V9: 11.583264 | W9: 11.896448 | X9: 29.322212 | Y9: 20.421544 | Z9: 12.159065 | AA9: 27.919623
B10: 700817 | C10: 0.962508 | D10: 1.40331 | E10: 3.654854 | F10: 36.398252 | G10: 13.449436 | H10: 667.94204 | I10: 0 | J10: 0 | K10: 158.1906 | L10: 0 | M10: 0 | N10: 60.615618 | O10: 35.063921 | P10: 8.247537 | Q10: 5.814374 | R10: 15.333448 | S10: 107.08462 | T10: 20.52232 | U10: 6.16246 | V10: 8.671138 | W10: 6.297737 | X10: 36.049713 | Y10: 20.159068 | Z10: 17.489306 | AA10: 41.280809
B11: 700818 | C11: 0.959803 | D11: 1.151615 | E11: 4.596197 | F11: 46.459816 | G11: 5.839761 | H11: 195.22178 | I11: 0 | J11: 0 | K11: 8.32614 | L11: 0 | M11: 0 | N11: 44.371486 | O11: 20.411087 | P11: 4.649191 | Q11: 3.286332 | R11: 15.117903 | S11: 73.005347 | T11: 11.825703 | U11: 4.064948 | V11: 7.034129 | W11: 2.52051 | X11: 15.700525 | Y11: 14.134182 | Z11: 13.569482 | AA11: 19.393675
B12: 700819 | C12: 2.508346 | D12: 4.334814 | E12: 2.949009 | F12: 18.853192 | G12: 0.999043 | H12: 36.674651 | I12: 154.14749 | J12: 14.205725 | K12: 0 | L12: 4.201745 | M12: 0 | N12: 31.779966 | O12: 15.439671 | P12: 3.46123 | Q12: 3.053062 | R12: 14.192204 | S12: 36.563621 | T12: 12.071421 | U12: 2.464896 | V12: 3.765819 | W12: 2.250539 | X12: 23.343215 | Y12: 11.548715 | Z12: 13.984092 | AA12: 20.325012
B13: 700820 | C13: 2.039776 | D13: 0.412063 | E13: 0.807716 | F13: 19.164033 | G13: 3.114837 | H13: 117.5591 | I13: 0 | J13: 0 | K13: 3.279547 | L13: 0 | M13: 0 | N13: 16.656647 | O13: 9.135261 | P13: 2.213917 | Q13: 2.761521 | R13: 4.630014 | S13: 16.782833 | T13: 6.792895 | U13: 1.384284 | V13: 1.909791 | W13: 1.932042 | X13: 16.164059 | Y13: 6.128699 | Z13: 4.67775 | AA13: 18.154378
B14: 701022 | C14: 0.060561 | D14: 0.046015 | E14: 0.230946 | F14: 1.266335 | G14: 0 | H14: 0 | I14: 0 | J14: 0 | K14: 0 | L14: 0 | M14: 0 | N14: 10.930239 | O14: 6.417064 | P14: 0.865991 | Q14: 0.826443 | R14: 0.160515 | S14: 0 | T14: 2.090177 | U14: 2.827799 | V14: 1.708713 | W14: 1.225467 | X14: 0 | Y14: 0 | Z14: 0 | AA14: 0
B15: 738101 | C15: 7.368666 | D15: 6.123817 | E15: 2.707752 | F15: 13.941818 | G15: 5.748701 | H15: 35.757355 | I15: 43.789593 | J15: 23.410953 | K15: 18.183799 | L15: 3.984254 | M15: 7.840692 | N15: 14.2 | O15: 35.519585 | P15: 8.001708 | Q15: 5.79101 | R15: 14.218583 | S15: 29.19697 | T15: 10.78054 | U15: 3.678909 | V15: 6.634478 | W15: 3.444003 | X15: 16.905755 | Y15: 9.000915 | Z15: 19.436704 | AA15: 11.584611
... B28: 738153 | C28: 0.481349 | D28: 0.475995 | E28: 0.423951 | F28: 1.847753 | G28: 0.558295 | H28: 5.121743 | I28: 6.165287 | J28: 1.464497 | K28: 3.242066 | L28: 2.694383 | M28: 0 | N28: 5.07046 | O28: 3.034549 | P28: 0.791008 | Q28: 0.576374 | R28: 1.602014 | S28: 0.723349 | T28: 0.839699 | U28: 0.274931 | V28: 0.873881 | W28: 0.356097 | X28: 0.984984 | Y28: 1.009578 | Z28: 3.381145 | AA28: 0
A30: Grundmatris Sampers 2019 (lbu+lbs)
C32: 700611 | D32: 700612 | E32: 700613 | F32: 700614 | G32: 700715 | H32: 700716 | I32: 700817 | J32: 700818 | K32: 700819 | L32: 700820 | M32: 701022 | N32: 738101 | O32: 738102 | P32: 738103 | Q32: 738104 | R32: 738105 | S32: 738107 | T32: 738108 | U32: 738109 | V32: 738110 | W32: 738111 | X32: 738112 | Y32: 738151 | Z32: 738152 | AA32: 738153
B33: 700611 | C33: 0 | D33: 0 | E33: 0.000278 | F33: 0.03893 | G33: 0.005258 | H33: 0.081995 | I33: 0 | J33: 0 | K33: 0.025343 | L33: 0.004385 | M33: 0.000281 | N33: 0.006911 | O33: 0.001994 | P33: 0.000666 | Q33: 0.000475 | R33: 0.001327 | S33: 0.014794 | T33: 0.001063 | U33: 0.000309 | V33: 0.000341 | W33: 0.000233 | X33: 0.002332 | Y33: 0.003059 | Z33: 0.000449 | AA33: 0.004312
B34: 700612 | C34: 0 | D34: 0 | E34: 0.000825 | F34: 0.091484 | G34: 0.015091 | H34: 0.246412 | I34: 0 | J34: 0 | K34: 0.064846 | L34: 0.003221 | M34: 0.000863 | N34: 0.017984 | O34: 0.005088 | P34: 0.002283 | Q34: 0.000786 | R34: 0.002199 | S34: 0.026734 | T34: 0.001783 | U34: 0.000566 | V34: 0.000669 | W34: 0.000335 | X34: 0.005437 | Y34: 0.013864 | Z34: 0.000902 | AA34: 0.007745
B35: 700613 | C35: 0.000278 | D35: 0.000825 | E35: 0 | F35: 0.019846 | G35: 0.00239 | H35: 0.043568 | I35: 0.051252 | J35: 0.0419 | K35: 0.011027 | L35: 0.002039 | M35: 0.000127 | N35: 0.003907 | O35: 0.001247 | P35: 0.000346 | Q35: 0.000275 | R35: 0.000822 | S35: 0.007393 | T35: 0.000708 | U35: 0.000218 | V35: 0.000232 | W35: 0.000153 | X35: 0.001297 | Y35: 0.001501 | Z35: 0.000276 | AA35: 0.002491
B36: 700614 | C36: 0.03893 | D36: 0.091484 | E36: 0.019846 | F36: 0 | G36: 0 | H36: 0 | I36: 1.198191 | J36: 2.404486 | K36: 5.306473 | L36: 5.44277 | M36: 0.015598 | N36: 0.418083 | O36: 0.171082 | P36: 0.05294 | Q36: 0.03665 | R36: 0.104739 | S36: 0.860147 | T36: 0.096836 | U36: 0.030751 | V36: 0.031586 | W36: 0.019088 | X36: 0.200479 | Y36: 0.343052 | Z36: 0.037361 | AA36: 0.256482
B37: 700715 | C37: 0.005258 | D37: 0.015091 | E37: 0.00239 | F37: 0 | G37: 0 | H37: 0 | I37: 0.432221 | J37: 0.104412 | K37: 0.003651 | L37: 0.093084 | M37: 0 | N37: 0.077125 | O37: 0.315696 | P37: 0.007933 | Q37: 0.004154 | R37: 0.011103 | S37: 0.122079 | T37: 0.006529 | U37: 0.002163 | V37: 0.002335 | W37: 0.001508 | X37: 0.007472 | Y37: 0.038339 | Z37: 0.004468 | AA37: 0.020457
B38: 700716 | C38: 0.081995 | D38: 0.246412 | E38: 0.043568 | F38: 0 | G38: 0 | H38: 0 | I38: 33.27233 | J38: 5.227588 | K38: 0.002289 | L38: 7.184312 | M38: 0 | N38: 0.703211 | O38: 0 | P38: 0.104264 | Q38: 0.076317 | R38: 0.185297 | S38: 0.606636 | T38: 0.118841 | U38: 0.06336 | V38: 0.066322 | W38: 0.043587 | X38: 0.21497 | Y38: 0.268631 | Z38: 0.065668 | AA38: 0.298068
B39: 700817 | C39: 0 | D39: 0 | E39: 0.051252 | F39: 1.198627 | G39: 0.432938 | H39: 33.37118 | I39: 0 | J39: 0 | K39: 8.311441 | L39: 0 | M39: 0 | N39: 1.031378 | O39: 0.417001 | P39: 0.096373 | Q39: 0.103035 | R39: 0.320598 | S39: 2.260973 | T39: 0.296714 | U39: 0.087152 | V39: 0.096441 | W39: 0.052904 | X39: 0.416967 | Y39: 0.409099 | Z39: 0.106629 | AA39: 0.704504
B40: 700818 | C40: 0 | D40: 0 | E40: 0.0419 | F40: 2.404661 | G40: 0.104412 | H40: 5.227588 | I40: 0 | J40: 0 | K40: 0.113849 | L40: 0 | M40: 0 | N40: 1.091147 | O40: 0.320671 | P40: 0.062966 | Q40: 0.067203 | R40: 0.201053 | S40: 4.057766 | T40: 0.19642 | U40: 0.018633 | V40: 0.065914 | W40: 0.014089 | X40: 0.079114 | Y40: 0.288362 | Z40: 0.07418 | AA40: 0.137697
B41: 700819 | C41: 0.025343 | D41: 0.064846 | E41: 0.011027 | F41: 5.306473 | G41: 0.003651 | H41: 0.002289 | I41: 8.311902 | J41: 0.113849 | K41: 0 | L41: 0.029349 | M41: 0 | N41: 0.397524 | O41: 0.092665 | P41: 0.037707 | Q41: 0.016558 | R41: 0.044336 | S41: 1.288386 | T41: 0.043787 | U41: 9.5e-05 | V41: 0.012395 | W41: 0.000164 | X41: 0.145869 | Y41: 0.165408 | Z41: 0.023844 | AA41: 0.253655
B42: 700820 | C42: 0.004385 | D42: 0.003221 | E42: 0.002039 | F42: 5.444529 | G42: 0.093084 | H42: 7.184312 | I42: 0 | J42: 0 | K42: 0.029349 | L42: 0 | M42: 0 | N42: 0.058878 | O42: 0.017479 | P42: 0.006649 | Q42: 0.003144 | R42: 0.008606 | S42: 0.124526 | T42: 0.008727 | U42: 0.038405 | V42: 0.002946 | W42: 0.025149 | X42: 0.205969 | Y42: 0.037846 | Z42: 0.00448 | AA42: 0.416853
B43: 701022 | C43: 0.000281 | D43: 0.000863 | E43: 0.000127 | F43: 0.015598 | G43: 0 | H43: 0 | I43: 0 | J43: 0 | K43: 0 | L43: 0 | M43: 0 | N43: 0.002931 | O43: 0.000904 | P43: 0.000515 | Q43: 0.000173 | R43: 0.000328 | S43: 0 | T43: 0.002898 | U43: 0.01175 | V43: 0.000862 | W43: 0.008781 | X43: 0 | Y43: 0 | Z43: 0 | AA43: 0
B44: 738101 | C44: 0.006911 | D44: 0.017984 | E44: 0.003907 | F44: 0.418083 | G44: 0.077125 | H44: 0.703211 | I44: 1.031378 | J44: 1.091147 | K44: 0.397524 | L44: 0.058878 | M44: 0.002931 | N44: 0 | O44: 0.030133 | P44: 0.006647 | Q44: 0.006407 | R44: 0.019059 | S44: 0.150896 | T44: 0.017728 | U44: 0.005722 | V44: 0.006033 | W44: 0.003904 | X44: 0.027257 | Y44: 0.025085 | Z44: 0.006421 | AA44: 0.055957
... B57: 738153 | C57: 0.004312 | D57: 0.007745 | E57: 0.002491 | F57: 0.256482 | G57: 0.020457 | H57: 0.298068 | I57: 0.704504 | J57: 0.137697 | K57: 0.253655 | L57: 0.416853 | M57: 0 | N57: 0.055957 | O57: 0.019552 | P57: 0.003881 | Q57: 0.00404 | R57: 0.012595 | S57: 0.097805 | T57: 0.012789 | U57: 0.004101 | V57: 0.004266 | W57: 0.002722 | X57: 0.01837 | Y57: 0.014754 | Z57: 0.00442 | AA57: 0
B60: Steg 1:
B61: Höja/sänka grundmatrisen i ytterzonerna då sampers underksattade en del från dessa baserat på mätningar från kommunen men framförallt trafikverkets vägar (NVDB mätningar). Gjorde det manuellt innan kalibreringsverktyget användes i Dynameq
B62: Detta är bara Pb/pby matrisen
C63: 700611 | D63: 700612 | E63: 700613 | F63: 700614 | G63: 700715 | H63: 700716 | I63: 700817 | J63: 700818 | K63: 700819 | L63: 700820 | M63: 701022 | N63: 738101 | O63: 738102 | P63: 738103 | Q63: 738104 | R63: 738105 | S63: 738107 | T63: 738108 | U63: 738109 | V63: 738110 | W63: 738111 | X63: 738112 | Y63: 738151 | Z63: 738152 | AA63: 738153
B64: 700611 | F64: 8.279646 | G64: 3.3494025 | N64: 7.2301464 | O64: 4.0700304 | P64: 0.7425228 | Q64: 0.5999334 | R64: 1.3228422 | S64: 4.5131874 | T64: 0.9807138 | U64: 0.3538608 | V64: 0.6873966 | W64: 0.553851 | X64: 1.2866298 | Y64: 1.7118804 | Z64: 2.1728778 | AA64: 8.654352
B65: 700612 | F65: 5.2604355 | G65: 4.2702025 | N65: 7.248423 | O65: 3.034228 | P65: 0.7780795 | Q65: 0.4949655 | R65: 2.763147 | S65: 6.0253485 | T65: 0.8358785 | U65: 0.5986425 | V65: 1.2919455 | W65: 0.739273 | X65: 2.62321 | Y65: 1.9582775 | Z65: 1.302044 | AA65: 10.63834
B66: 700613 | F66: 11.602293 | G66: 9.21022 | N66: 5.928004 | O66: 2.2993168 | P66: 0.4549924 | Q66: 0.5885224 | R66: 1.8326484 | S66: 3.8741024 | T66: 0.3568728 | U66: 0.7274044 | V66: 0.4248408 | W66: 0.410686 | X66: 0.9893636 | Y66: 1.5090288 | Z66: 0.6612484 | AA66: 1.8702316
B67: 700614
B68: 700715
B69: 700716 | I69: -200
...

Sheet Uppdelningstal
A1: Nya zoner | B1: Originalzon Sampers | C1: Kommentar | D1: Andel nattbefolkning (till resor EM) | E1: Andel dagbefolkning (frånresor EM)
A2: 1 | B2: 700611 | D2: 1 | E2: 1
A3: 2 | B3: 700612 | D3: 1 | E3: 1
A4: 3 | B4: 700613 | D4: 1 | E4: 1
A5: 4 | B5: 700614 | D5: 1 | E5: 1
A6: 5 | B6: 700715 | D6: 1 | E6: 1
A7: 6 | B7: 700716 | D7: 1 | E7: 1
A8: 7 | B8: 700817 | D8: 1 | E8: 1
A9: 8 | B9: 700818 | D9: 1 | E9: 1
A10: 9 | B10: 700819 | D10: 1 | E10: 1
A11: 10 | B11: 700820 | D11: 1 | E11: 1
A12: 11 | B12: 701022 | D12: 1 | E12: 1
A13: 7381011 | B13: 738101 | D13: 0.01 | E13: 0.05
... A80: 7381534 | B80: 738153 | D80: 0.25 | E80: 0.2
A81: 13 | B81: 13 | C81: pendlar p norr
A82: 14 | B82: 14 | C82: pendlar p syd
A83: 15 | B83: 15 | C83: ny industrizon

Sheet Uppdelad pb matris
A1: Steg 3: Uppdelad pb/pby matris ink nya zoner.
C2: 1 | D2: 2 | E2: 3 | F2: 4 | G2: 5 | H2: 6 | I2: 7 | J2: 8 | K2: 9 | L2: 10 | M2: 11 | N2: 7381011 | O2: 7381012 | P2: 7381013 | Q2: 7381014 | R2: 7381015 | S2: 7381016 | T2: 7381017 | U2: 7381018 | V2: 7381021 | W2: 7381022 | X2: 7381023 | Y2: 7381024 | Z2: 7381031 | AA2: 7381032 | AB2: 7381033 | AC2: 7381034 | AD2: 7381041 | AE2: 7381042 | AF2: 7381043 | AG2: 7381044 | AH2: 7381051 | AI2: 7381052 | AJ2: 7381053 | AK2: 7381054 | AL2: 7381055 | AM2: 7381071 | AN2: 7381072 | AO2: 7381073 | AP2: 7381074 | AQ2: 7381075 | AR2: 7381076 | AS2: 7381077 | AT2: 7381081 | AU2: 7381082 | AV2: 7381083 | AW2: 7381084 | AX2: 7381085 | AY2: 7381086 | AZ2: 7381091 | BA2: 7381092 | BB2: 7381092 | BC2: 7381101 | BD2: 7381102 | BE2: 7381103 | BF2: 7381111 | BG2: 7381112 | BH2: 7381113 | BI2: 7381121 | BJ2: 7381122 | BK2: 7381123 | BL2: 7381124 | BM2: 7381511 | BN2: 7381512 | BO2: 7381513 | BP2: 7381514 | BQ2: 7381515 | BR2: 7381516 | BS2: 7381517 | BT2: 7381518 | BU2: 7381521 | BV2: 7381522 | BW2: 7381523 | BX2: 7381524 | BY2: 7381525 | BZ2: 7381531 | CA2: 7381532 | CB2: 7381533 | CC2: 7381534 | CD2: 13 | CE2: 14 | CF2: 15
B3: 1 | C3: 0 | D3: 0 | E3: 0.733032 | F3: 13.79941 | G3: 4.6891635 | H3: 13.100322 | I3: 3.662453 | J3: 1.439829 | K3: 4.319857 | L3: 0.613063 | M3: 0.060561 | N3: 0.1928039 | O3: 2.8920586 | P3: 4.6272937 | Q3: 4.6272937 | R3: 5.7841171 | S3: 0.57841171 | T3: 0.1928039 | U3: 0.38560781 | V3: 2.7133536 | W3: 1.6280122 | X3: 1.6280122 | Y3: 4.8840365 | Z3: 0.97022979 | AA3: 0.77222371 | AB3: 0.039601216 | AC3: 0.19800608 | AD3: 0.31996448 | AE3: 0.63992896 | AF3: 0.3999556 | AG3: 0.23997336 | AH3: 1.9048928 | AI3: 0.70551584 | AJ3: 0.70551584 | AK3: 0.10582738 | AL3: 0.10582738 | AM3: 0.24070333 | AN3: 8.9060231 | AO3: 0.60175832 | AP3: 0.24070333 | AQ3: 0.60175832 | AR3: 1.2035166 | AS3: 0.24070333 | AT3: 0.49689499 | AU3: 0.62765683 | AV3: 0.052304736 | AW3: 0.39228552 | AX3: 0.99378998 | AY3: 0.052304736 | AZ3: 0.56617728 | BA3: 0.18872576 | BB3: 0.18872576 | BC3: 1.4664461 | BD3: 0.36661152 | BE3: 0 | BF3: 0.0369234 | BG3: 1.4030892 | BH3: 0.0369234 | BI3: 0.17155064 | BJ3: 0.068620256 | BK3: 2.8477406 | BL3: 0.34310128 | BM3: 0.11412536 | BN3: 0.91300288 | BO3: 0.5706268 | BP3: 0.68475216 | BQ3: 0.5706268 | BR3: 0.11412536 | BS3: 0.91300288 | BT3: 0.68475216 | BU3: 1.9700759 | BV3: 0.57943408 | BW3: 2.2597929 | BX3: 0.86915112 | BY3: 0.11588682 | BZ3: 3.245382 | CA3: 3.245382 | CB3: 3.245382 | CC3: 3.245382 | CD3: 0.3673516 | CE3: 0.047080808 | CF3: 0.45444796 | CH3: =SUM(C3:CF3) -> 126.20376
B4: 2 | C4: 0 | D4: 0 | E4: 2.193773 | F4: 8.7673925 | G4: 5.9782835 | H4: 25.612949 | I4: 3.594923 | J4: 2.797354 | K4: 4.35267 | L4: 1.133021 | M4: 0.046015 | N4: 0.21745269 | O4: 3.2617904 | P4: 5.2188646 | Q4: 5.2188646 | R4: 6.5235807 | S4: 0.65235807 | T4: 0.21745269 | U4: 0.43490538 | V4: 2.275671 | W4: 1.3654026 | X4: 1.3654026 | Y4: 4.0962078 | Z4: 1.1437769 | AA4: 0.91035302 | AB4: 0.04668477 | AC4: 0.23342385 | AD4: 0.2969793 | AE4: 0.5939586 | AF4: 0.37122413 | AG4: 0.22273448 | AH4: 4.4762981 | AI4: 1.6578882 | AJ4: 1.6578882 | AK4: 0.24868323 | AL4: 0.24868323 | AM4: 0.36152091 | AN4: 13.376274 | AO4: 0.90380227 | AP4: 0.36152091 | AQ4: 0.90380227 | AR4: 1.8076045 | AS4: 0.36152091 | AT4: 0.47645075 | AU4: 0.60183252 | AV4: 0.05015271 | AW4: 0.37614533 | AX4: 0.95290149 | AY4: 0.05015271 | AZ4: 1.0775565 | BA4: 0.3591855 | BB4: 0.3591855 | BC4: 3.1006692 | BD4: 0.7751673 | BE4: 0 | BF4: 0.055445475 | BG4: 2.1069281 | BH4: 0.055445475 | BI4: 0.3934815 | BJ4: 0.1573926 | BK4: 6.5317929 | BL4: 0.786963 | BM4: 0.14687081 | BN4: 1.1749665 | BO4: 0.73435406 | BP4: 0.88122488 | BQ4: 0.73435406 | BR4: 0.14687081 | BS4: 1.1749665 | BT4: 0.88122488 | BU4: 1.3280849 | BV4: 0.3906132 | BW4: 1.5233915 | BX4: 0.5859198 | BY4: 0.07812264 | BZ4: 3.9893775 | CA4: 3.9893775 | CB4: 3.9893775 | CC4: 3.9893775 | CD4: 0.45156601 | CE4: 0.057873963 | CF4: 0.55862899 | CH4: =SUM(C4:CF4) -> 160.58235
B5: 3 | C5: 2.979703 | D5: 1.434597 | E5: 0 | F5: 19.337155 | G5: 12.894308 | H5: 23.219633 | I5: 23.498498 | J5: 14.212009 | K5: 5.310744 | L5: 1.617766 | M5: 0.631449 | N5: 0.20748014 | O5: 3.1122021 | P5: 4.9795234 | Q5: 4.9795234 | R5: 6.2244042 | S5: 0.62244042 | T5: 0.20748014 | U5: 0.41496028 | V5: 2.0119022 | W5: 1.2071413 | X5: 1.2071413 | Y5: 3.621424 | Z5: 0.78031197 | AA5: 0.62106463 | AB5: 0.031849468 | AC5: 0.15924734 | AD5: 0.41196568 | AE5: 0.82393136 | AF5: 0.5149571 | AG5: 0.30897426 | AH5: 3.4637055 | AI5: 1.2828539 | AJ5: 1.2828539 | AK5: 0.19242808 | AL5: 0.19242808 | AM5: 0.27118717 | AN5: 10.033925 | AO5: 0.67796792 | AP5: 0.27118717 | AQ5: 0.67796792 | AR5: 1.3559358 | AS5: 0.27118717 | AT5: 0.23732041 | AU5: 0.29977315 | AV5: 0.024981096 | AW5: 0.18735822 | AX5: 0.47464082 | AY5: 0.024981096 | AZ5: 1.5275492 | BA5: 0.50918308 | BB5: 0.50918308 | BC5: 1.1895542 | BD5: 0.29738856 | BE5: 0 | BF5: 0.035935025 | BG5: 1.365531 | BH5: 0.035935025 | BI5: 0.17313863 | BJ5: 0.069255452 | BK5: 2.8741013 | BL5: 0.34627726 | BM5: 0.13204002 | BN5: 1.0563202 | BO5: 0.6602001 | BP5: 0.79224012 | BQ5: 0.6602001 | BR5: 0.13204002 | BS5: 1.0563202 | BT5: 0.79224012 | BU5: 0.7868856 | BV5: 0.23143694 | BW5: 0.90260407 | BX5: 0.34715541 | BY5: 0.046287388 | BZ5: 1.6364527 | CA5: 1.6364527 | CB5: 1.6364527 | CC5: 1.6364527 | CD5: 0.39692895 | CE5: 0.050871524 | CF5: 0.49103788 | CH5: =SUM(C5:CF5) -> 182.82012
B6: 4 | C6: 2.762057 | D6: 4.063984 | E6: 1.391482 | F6: 0 | G6: 16.61195 | H6: 0 | I6: 61.001679 | J6: 56.557619 | K6: 29.108081 | L6: 16.433524 | M6: 1.972008 | N6: 0.37849767 | O6: 5.677465 | P6: 9.0839441 | Q6: 9.0839441 | R6: 11.35493 | S6: 1.135493 | T6: 0.37849767 | U6: 0.75699534 | V6: 5.1129587 | W6: 3.0677752 | X6: 3.0677752 | Y6: 9.2033257 | Z6: 0.97959232 | AA6: 0.77967552 | AB6: 0.03998336 | AC6: 0.1999168 | AD6: 0.5414902 | AE6: 1.0829804 | AF6: 0.67686275 | AG6: 0.40611765 | AH6: 4.6809992 | AI6: 1.7337034 | AJ6: 1.7337034 | AK6: 0.26005551 | AL6: 0.26005551 | AM6: 0.46919076 | AN6: 17.360058 | AO6: 1.1729769 | AP6: 0.46919076 | AQ6: 1.1729769 | AR6: 2.3459538 | AS6: 0.46919076 | AT6: 1.374581 | AU6: 1.7363129 | AV6: 0.14469274 | AW6: 1.0851955 | AX6: 2.7491621 | AY6: 0.14469274 | AZ6: 2.9920008 | BA6: 0.9973336 | BB6: 0.9973336 | BC6: 2.926104 | BD6: 0.731526 | BE6: 0 | BF6: 0.10322048 | BG6: 3.922378 | BH6: 0.10322048 | BI6: 0.477607 | BJ6: 0.1910428 | BK6: 7.9282762 | BL6: 0.955214 | BM6: 0.19785108 | BN6: 1.5828086 | BO6: 0.98925538 | BP6: 1.1871064 | BQ6: 0.98925538 | BR6: 0.19785108 | BS6: 1.5828086 | BT6: 1.1871064 | BU6: 1.7928628 | BV6: 0.5273126 | BW6: 2.0565191 | BX6: 0.7909689 | BY6: 0.10546252 | BZ6: 4.229731 | CA6: 4.229731 | CB6: 4.229731 | CC6: 4.229731 | CD6: 1.4363164 | CE6: 0.18408233 | CF6: 1.7768564 | CH6: =SUM(C6:CF6) -> 348.1019
B7: 5 | C7: 1.275342 | D7: 1.617101 | E7: 0.765046 | F7: 11.08358 | G7: 0 | H7: 3.724316 | I7: 29.665761 | J7: 9.893036 | K7: 0.52929 | L7: 1.305452 | M7: 0 | N7: 0.21740548 | O7: 3.2610822 | P7: 5.2177315 | Q7: 5.2177315 | R7: 6.5221644 | S7: 0.65221644 | T7: 0.21740548 | U7: 0.43481096 | V7: 4.4464862 | W7: 2.6678917 | X7: 2.6678917 | Y7: 8.0036752 | Z7: 0.85394946 | AA7: 0.67967406 | AB7: 0.03485508 | AC7: 0.1742754 | AD7: 0.5417874 | AE7: 1.0835748 | AF7: 0.67723425 | AG7: 0.40634055 | AH7: 2.4544647 | AI7: 0.909061 | AJ7: 0.909061 | AK7: 0.13635915 | AL7: 0.13635915 | AM7: 0.2187749 | AN7: 8.0946713 | AO7: 0.54693725 | AP7: 0.2187749 | AQ7: 0.54693725 | AR7: 1.0938745 | AS7: 0.2187749 | AT7: 0.70478657 | AU7: 0.89025672 | AV7: 0.07418806 | AW7: 0.55641045 | AX7: 1.4095731 | AY7: 0.07418806 | AZ7: 1.5397272 | BA7: 0.5132424 | BB7: 0.5132424 | BC7: 1.605028 | BD7: 0.401257 | BE7: 0 | BF7: 0.05888475 | BG7: 2.2376205 | BH7: 0.05888475 | BI7: 0.22546195 | BJ7: 0.09018478 | BK7: 3.7426684 | BL7: 0.4509239 | BM7: 0.09852395 | BN7: 0.7881916 | BO7: 0.49261975 | BP7: 0.5911437 | BQ7: 0.49261975 | BR7: 0.09852395 | BS7: 0.7881916 | BT7: 0.5911437 | BU7: 0.94779794 | BV7: 0.2787641 | BW7: 1.08718 | BX7: 0.41814615 | BY7: 0.05575282 | BZ7: 1.4840163 | CA7: 1.4840163 | CB7: 1.4840163 | CC7: 1.4840163 | CD7: 0.50393674 | CE7: 0.064585942 | CF7: 0.62341643 | CH7: =SUM(C7:CF7) -> 148.32429
B8: 6 | C8: 11.852271 | D8: 10.237136 | E8: 5.731874 | F8: 0 | G8: 1.568403 | H8: 0 | I8: 478.14585 | J8: 179.57556 | K8: 19.979292 | L8: 105.04038 | M8: 0 | N8: 0.64593383 | O8: 9.6890075 | P8: 15.502412 | Q8: 15.502412 | R8: 19.378015 | S8: 1.9378015 | T8: 0.64593383 | U8: 1.2918677 | V8: 6.7483772 | W8: 4.0490264 | X8: 4.0490264 | Y8: 12.147079 | Z8: 3.2404263 | AA8: 2.5791148 | AB8: 0.1322623 | AC8: 0.6613115 | AD8: 1.0419636 | AE8: 2.0839272 | AF8: 1.3024545 | AG8: 0.7814727 | AH8: 10.823664 | AI8: 4.0087644 | AJ8: 4.0087644 | AK8: 0.60131466 | AL8: 0.60131466 | AM8: 1.0974912 | AN8: 40.607174 | AO8: 2.743728 | AP8: 1.0974912 | AQ8: 2.743728 | AR8: 5.4874559 | AS8: 1.0974912 | AT8: 3.407672 | AU8: 4.3044278 | AV8: 0.35870232 | AW8: 2.6902674 | AX8: 6.8153441 | AY8: 0.35870232 | AZ8: 4.7990328 | BA8: 1.5996776 | BB8: 1.5996776 | BC8: 9.2666112 | BD8: 2.3166528 | BE8: 0 | BF8: 0.2974112 | BG8: 11.301626 | BH8: 0.2974112 | BI8: 1.4661106 | BJ8: 0.58644424 | BK8: 24.337436 | BL8: 2.9322212 | BM8: 0.5105386 | BN8: 4.0843088 | BO8: 2.552693 | BP8: 3.0632316 | BQ8: 2.552693 | BR8: 0.5105386 | BS8: 4.0843088 | BT8: 3.0632316 | BU8: 4.1340821 | BV8: 1.2159065 | BW8: 4.7420353 | BX8: 1.8238597 | BY8: 0.2431813 | BZ8: 6.9799057 | CA8: 6.9799057 | CB8: 6.9799057 | CC8: 6.9799057 | CD8: 0 | CE8: 0 | CF8: 0 | CH8: =SUM(C8:CF8) -> 1129.6946
B9: 7 | C9: 0.962508 | D9: 1.40331 | E9: 3.654854 | F9: 36.398252 | G9: 13.449436 | H9: 667.94204 | I9: 0 | J9: 0 | K9: 158.1906 | L9: 0 | M9: 0 | N9: 0.64252555 | O9: 9.6378833 | P9: 15.420613 | Q9: 15.420613 | R9: 19.275767 | S9: 1.9275767 | T9: 0.64252555 | U9: 1.2850511 | V9: 9.2919391 | W9: 5.5751634 | X9: 5.5751634 | Y9: 16.72549 | Z9: 4.2837707 | AA9: 3.4095318 | AB9: 0.17484778 | AC9: 0.87423892 | AD9: 1.2326473 | AE9: 2.4652946 | AF9: 1.5408091 | AG9: 0.92448547 | AH9: 8.7768656 | AI9: 3.250691 | AJ9: 3.250691 | AK9: 0.48760365 | AL9: 0.48760365 | AM9: 2.2701939 | AN9: 83.997176 | AO9: 5.6754849 | AP9: 2.2701939 | AQ9: 5.6754849 | AR9: 11.35097 | AS9: 2.2701939 | AT9: 4.1331952 | AU9: 5.2208782 | AV9: 0.43507318 | AW9: 3.2630489 | AX9: 8.2663905 | AY9: 0.43507318 | AZ9: 3.9193246 | BA9: 1.3064415 | BB9: 1.3064415 | BC9: 7.353125 | BD9: 1.8382813 | BE9: 0 | BF9: 0.16689003 | BG9: 6.3418212 | BH9: 0.16689003 | BI9: 1.8024856 | BJ9: 0.72099426 | BK9: 29.921262 | BL9: 3.6049713 | BM9: 0.5039767 | BN9: 4.0318136 | BO9: 2.5198835 | BP9: 3.0238602 | BQ9: 2.5198835 | BR9: 0.5039767 | BS9: 4.0318136 | BT9: 3.0238602 | BU9: 6.3031459 | BV9: 1.8538664 | BW9: 7.2300791 | BX9: 2.7807997 | BY9: 0.37077329 | BZ9: 10.320202 | CA9: 10.320202 | CB9: 10.320202 | CC9: 10.320202 | CD9: 0 | CE9: 0 | CF9: 0 | CH9: =SUM(C9:CF9) -> 1288.2712
B10: 8 | C10: 0.959803 | D10: 1.151615 | E10: 4.596197 | F10: 116.14954 | G10: 20.439163 | H10: 195.22178 | I10: 0 | J10: 0 | K10: 8.32614 | L10: 0 | M10: 0 | N10: 0.61232651 | O10: 9.1848976 | P10: 14.695836 | Q10: 14.695836 | R10: 18.369795 | S10: 1.8369795 | T10: 0.61232651 | U10: 1.224653 | V10: 7.041825 | W10: 4.225095 | X10: 4.225095 | Y10: 12.675285 | Z10: 3.143783 | AA10: 2.5021946 | AB10: 0.12831767 | AC10: 0.64158836 | AD10: 0.90702763 | AE10: 1.8140553 | AF10: 1.1337845 | AG10: 0.68027072 | AH10: 11.265861 | AI10: 4.1725412 | AJ10: 4.1725412 | AK10: 0.62588118 | AL10: 0.62588118 | AM10: 2.0149476 | AN10: 74.55306 | AO10: 5.0373689 | AP10: 2.0149476 | AQ10: 5.0373689 | AR10: 10.074738 | AS10: 2.0149476 | AT10: 3.1006993 | AU10: 3.9166728 | AV10: 0.3263894 | AW10: 2.4479205 | AX10: 6.2013987 | AY10: 0.3263894 | AZ10: 3.3657769 | BA10: 1.1219256 | BB10: 1.1219256 | BC10: 7.7656784 | BD10: 1.9414196 | BE10: 0 | BF10: 0.086957595 | BG10: 3.3043886 | BH10: 0.086957595 | BI10: 0.78502625 | BJ10: 0.3140105 | BK10: 13.031436 | BL10: 1.5700525 | BM10: 0.35335455 | BN10: 2.8268364 | BO10: 1.7667727 | BP10: 2.1201273 | BQ10: 1.7667727 | BR10: 0.35335455 | BS10: 2.8268364 | BT10: 2.1201273 | BU10: 6.366801 | BV10: 1.8725885 | BW10: 7.3030952 | BX10: 2.8088828 | BY10: 0.3745177 | BZ10: 4.8484187 | CA10: 4.8484187 | CB10: 4.8484187 | CC10: 4.8484187 | CD10: 1.6464081 | CE10: 0.21100826 | CF10: 2.0367593 | CH10: =SUM(C10:CF10) -> 675.76824
B11: 9 | C11: 2.508346 | D11: 4.334814 | E11: 2.949009 | F11: 18.853192 | G11: 0.999043 | H11: 36.674651 | I11: 134.14749 | J11: 14.205725 | K11: 0 | L11: 4.201745 | M11: 0 | N11: 0.31779966 | O11: 4.7669949 | P11: 7.6271918 | Q11: 7.6271918 | R11: 9.5339898 | S11: 0.95339898 | T11: 0.31779966 | U11: 0.63559932 | V11: 3.8599178 | W11: 2.3159506 | X11: 2.3159506 | Y11: 6.947852 | Z11: 1.6960027 | AA11: 1.3498797 | AB11: 0.0692246 | AC11: 0.346123 | AD11: 0.6106124 | AE11: 1.2212248 | AF11: 0.7632655 | AG11: 0.4579593 | AH11: 7.6637902 | AI11: 2.8384408 | AJ11: 2.8384408 | AK11: 0.42576612 | AL11: 0.42576612 | AM11: 0.73127242 | AN11: 27.05708 | AO11: 1.828181 | AP11: 0.73127242 | AQ11: 1.828181 | AR11: 3.6563621 | AS11: 0.73127242 | AT11: 2.29357 | AU11: 2.897141 | AV11: 0.24142842 | AW11: 1.8107131 | AX11: 4.58714 | AY11: 0.24142842 | AZ11: 1.4789376 | BA11: 0.4929792 | BB11: 0.4929792 | BC11: 3.0126552 | BD11: 0.7531638 | BE11: 0 | BF11: 0.056263475 | BG11: 2.138012 | BH11: 0.056263475 | BI11: 1.1671608 | BJ11: 0.4668643 | BK11: 19.374868 | BL11: 2.3343215 | BM11: 0.28871788 | BN11: 2.309743 | BO11: 1.4435894 | BP11: 1.7323073 | BQ11: 1.4435894 | BR11: 0.28871788 | BS11: 2.309743 | BT11: 1.7323073 | BU11: 4.7545913 | BV11: 1.3984092 | BW11: 5.4537959 | BX11: 2.0976138 | BY11: 0.27968184 | BZ11: 5.081253 | CA11: 5.081253 | CB11: 5.081253 | CC11: 5.081253 | CD11: 1.7254731 | CE11: 0.22114146 | CF11: 2.13457 | CH11: =SUM(C11:CF11) -> 417.19866
B12: 10 | C12: 2.039776 | D12: 0.412063 | E12: 0.807716 | F12: 19.164033 | G12: 3.114837 | H12: 117.5591 | I12: 0 | J12: 0 | K12: 3.279547 | L12: 0 | M12: 0 | N12: 0.16656647 | O12: 2.498497 | P12: 3.9975953 | Q12: 3.9975953 | R12: 4.9969941 | S12: 0.49969941 | T12: 0.16656647 | U12: 0.33313294 | V12: 2.2838153 | W12: 1.3702892 | X12: 1.3702892 | Y12: 4.1108675 | Z12: 1.0848193 | AA12: 0.86342763 | AB12: 0.04427834 | AC12: 0.2213917 | AD12: 0.5523042 | AE12: 1.1046084 | AF12: 0.69038025 | AG12: 0.41422815 | AH12: 2.5002076 | AI12: 0.9260028 | AJ12: 0.9260028 | AK12: 0.13890042 | AL12: 0.13890042 | AM12: 0.33565666 | AN12: 12.419296 | AO12: 0.83914165 | AP12: 0.33565666 | AQ12: 0.83914165 | AR12: 1.6782833 | AS12: 0.33565666 | AT12: 1.29065 | AU12: 1.6302948 | AV12: 0.1358579 | AW12: 1.0189342 | AX12: 2.5813001 | AY12: 0.1358579 | AZ12: 0.8305704 | BA12: 0.2768568 | BB12: 0.2768568 | BC12: 1.5278328 | BD12: 0.3819582 | BE12: 0 | BF12: 0.04830105 | BG12: 1.8354399 | BH12: 0.04830105 | BI12: 0.80820295 | BJ12: 0.32328118 | BK12: 13.416169 | BL12: 1.6164059 | BM12: 0.15321748 | BN12: 1.2257398 | BO12: 0.76608738 | BP12: 0.91930485 | BQ12: 0.76608738 | BR12: 0.15321748 | BS12: 1.2257398 | BT12: 0.91930485 | BU12: 1.590435 | BV12: 0.467775 | BW12: 1.8243225 | BX12: 0.7016625 | BY12: 0.093555 | BZ12: 4.5385945 | CA12: 4.5385945 | CB12: 4.5385945 | CC12: 4.5385945 | CD12: 1.5411991 | CE12: 0.19752439 | CF12: 1.9066061 | CH12: =SUM(C12:CF12) -> 259.34649
B13: 11 | C13: 0.060561 | D13: 0.046015 | E13: 0.230946 | F13: 3.1658375 | G13: 0 | H13: 0 | I13: 0 | J13: 0 | K13: 0 | L13: 0 | M13: 0 | N13: 0.10930239 | O13: 1.6395358 | P13: 2.6232574 | Q13: 2.6232574 | R13: 3.2790717 | S13: 0.32790717 | T13: 0.10930239 | U13: 0.21860478 | V13: 1.604266 | W13: 0.9625596 | X13: 0.9625596 | Y13: 2.8876788 | Z13: 0.42433559 | AA13: 0.33773649 | AB13: 0.01731982 | AC13: 0.0865991 | AD13: 0.1652886 | AE13: 0.3305772 | AF13: 0.20661075 | AG13: 0.12396645 | AH13: 0.0866781 | AI13: 0.032103 | AJ13: 0.032103 | AK13: 0.00481545 | AL13: 0.00481545 | AM13: 0 | AN13: 0 | AO13: 0 | AP13: 0 | AQ13: 0 | AR13: 0 | AS13: 0 | AT13: 0.39713363 | AU13: 0.50164248 | AV13: 0.04180354 | AW13: 0.31352655 | AX13: 0.79426726 | AY13: 0.04180354 | AZ13: 1.6966794 | BA13: 0.5655598 | BB13: 0.5655598 | BC13: 1.3669704 | BD13: 0.3417426 | BE13: 0 | BF13: 0.030636675 | BG13: 1.1641937 | BH13: 0.030636675 | BI13: 0 | BJ13: 0 | BK13: 0 | BL13: 0 | BM13: 0 | BN13: 0 | BO13: 0 | BP13: 0 | BQ13: 0 | BR13: 0 | BS13: 0 | BT13: 0 | BU13: 0 | BV13: 0 | BW13: 0 | BX13: 0 | BY13: 0 | BZ13: 0 | CA13: 0 | CB13: 0 | CC13: 0 | CD13: 0 | CE13: 0 | CF13: 0 | CH13: =SUM(C13:CF13) -> 30.555767
B14: 7381011 | C14: 1.4737332 | D14: 1.8371451 | E14: 2.5046706 | F14: 1.7427273 | G14: 1.0060227 | H14: 1.7878677 | I14: 2.1894796 | J14: 1.9314036 | K14: 2.6366509 | L14: 0.85661461 | M14: 0.3920346 | N14: 0 | O14: 0.1065 | P14: 0.1704 | Q14: 0.1704 | R14: 0.213 | S14: 0.0213 | T14: 0.0071 | U14: 0.0142 | V14: 0.44399481 | W14: 0.26639689 | X14: 0.26639689 | Y14: 0.79919066 | Z14: 0.19604185 | AA14: 0.15603331 | AB14: 0.008001708 | AC14: 0.04000854 | AD14: 0.0579101 | AE14: 0.1158202 | AF14: 0.072387625 | AG14: 0.043432575 | AH14: 0.38390174 | AI14: 0.14218583 | AJ14: 0.14218583 | AK14: 0.021327874 | AL14: 0.021327874 | AM14: 0.02919697 | AN14: 1.0802879 | AO14: 0.072992425 | AP14: 0.02919697 | AQ14: 0.072992425 | AR14: 0.14598485 | AS14: 0.02919697 | AT14: 0.10241513 | AU14: 0.12936648 | AV14: 0.01078054 | AW14: 0.08085405 | AX14: 0.20483026 | AY14: 0.01078054 | AZ14: 0.11036727 | BA14: 0.03678909 | BB14: 0.03678909 | BC14: 0.26537912 | BD14: 0.06634478 | BE14: 0 | BF14: 0.0043050038 | BG14: 0.16359014 | BH14: 0.0043050038 | BI14: 0.042264388 | BJ14: 0.016905755 | BK14: 0.70158883 | BL14: 0.084528775 | BM14: 0.033753431 | BN14: 0.27002745 | BO14: 0.16876716 | BP14: 0.20252059 | BQ14: 0.16876716 | BR14: 0.033753431 | BS14: 0.27002745 | BT14: 0.20252059 | BU14: 0.9912719 | BV14: 0.29155056 | BW14: 1.1370472 | BX14: 0.43732584 | BY14: 0.058310112 | BZ14: 0.43442291 | CA14: 0.43442291 | CB14: 0.43442291 | CC14: 0.43442291 | CD14: 0.049173241 | CE14: 0.0063021801 | CF14: 0.060831854 | CH14: =SUM(C14:CF14) -> 31.889469
... B84: 15 | C84: 1.6922825 | D84: 1.6734594 | E84: 1.4904879 | F84: 6.49616 | G84: 1.9628022 | H84: 0 | I84: 0 | J84: 5.1487439 | K84: 0 | L84: 9.4726639 | M84: 0 | N84: 0.17826257 | O84: 2.6739385 | P84: 4.4565642 | Q84: 4.4565642 | R84: 5.3478771 | S84: 0.53478771 | T84: 0.17826257 | U84: 0 | V84: 4.2674353 | W84: 2.1337177 | X84: 2.1337177 | Y84: 5.3342941 | Z84: 1.3904766 | AA84: 1.1123813 | AB84: 0 | AC84: 0.27809532 | AD84: 0.40527254 | AE84: 0.81054508 | AF84: 0.50659067 | AG84: 0.3039544 | AH84: 2.8161067 | AI84: 1.4080534 | AJ84: 1.4080534 | AK84: 0 | AL84: 0 | AM84: 0 | AN84: 2.0344671 | AO84: 0.12715419 | AP84: 0 | AQ84: 0.12715419 | AR84: 0.25430839 | AS84: 0 | AT84: 0.5904273 | AU84: 0.73803413 | AV84: 0 | AW84: 0.44282048 | AX84: 1.1808546 | AY84: 0 | AZ84: 0.57994627 | BA84: 0.19331542 | BB84: 0.19331542 | BC84: 2.4578484 | BD84: 0.61446209 | BE84: 0 | BF84: 0.031298327 | BG84: 1.1893364 | BH84: 0.031298327 | BI84: 0.17314581 | BJ84: 0 | BK84: 2.9434787 | BL84: 0.34629161 | BM84: 0.088734537 | BN84: 0.70987629 | BO84: 0.44367268 | BP84: 0.53240722 | BQ84: 0.44367268 | BR84: 0.088734537 | BS84: 0.70987629 | BT84: 0.53240722 | BU84: 4.1604915 | BV84: 1.1887119 | BW84: 4.7548474 | BX84: 1.7830678 | BY84: 0 | BZ84: 0 | CA84: 0 | CB84: 0 | CC84: 0 | CD84: 0 | CE84: 0 | CF84: 0 | CH84: =SUM(C84:CF84) -> 99.757008
B86: Steg 4: Kalibrerad matris i dynameq
C87: 1 | D87: 2 | E87: 3 | F87: 4 | G87: 5 | H87: 6 | I87: 7 | J87: 8 | K87: 9 | L87: 10 | M87: 11 | N87: 7381011 | O87: 7381012 | P87: 7381013 | Q87: 7381014 | R87: 7381015 | S87: 7381016 | T87: 7381017 | U87: 7381018 | V87: 7381021 | W87: 7381022 | X87: 7381023 | Y87: 7381024 | Z87: 7381031 | AA87: 7381032 | AB87: 7381033 | AC87: 7381034 | AD87: 7381041 | AE87: 7381042 | AF87: 7381043 | AG87: 7381044 | AH87: 7381051 | AI87: 7381052 | AJ87: 7381053 | AK87: 7381054 | AL87: 7381055 | AM87: 7381071 | AN87: 7381072 | AO87: 7381073 | AP87: 7381074 | AQ87: 7381075 | AR87: 7381076 | AS87: 7381077 | AT87: 7381081 | AU87: 7381082 | AV87: 7381083 | AW87: 7381084 | AX87: 7381085 | AY87: 7381086 | AZ87: 7381091 | BA87: 7381092 | BB87: 7381092 | BC87: 7381101 | BD87: 7381102 | BE87: 7381103 | BF87: 7381111 | BG87: 7381112 | BH87: 7381113 | BI87: 7381121 | BJ87: 7381122 | BK87: 7381123 | BL87: 7381124 | BM87: 7381511 | BN87: 7381512 | BO87: 7381513 | BP87: 7381514 | BQ87: 7381515 | BR87: 7381516 | BS87: 7381517 | BT87: 7381518 | BU87: 7381521 | BV87: 7381522 | BW87: 7381523 | BX87: 7381524 | BY87: 7381525 | BZ87: 7381531 | CA87: 7381532 | CB87: 7381533 | CC87: 7381534 | CD87: 13 | CE87: 14 | CF87: 15
B88: 1 | C88: =('Hela matrisen pb 14-16'!B705/4)+('Hela matrisen pb 14-16'!B790/4)+('Hela matrisen pb 14-16'!B875/4)+('Hela matrisen pb 14-16'!B960/4) -> 0 | D88: =('Hela matrisen pb 14-16'!C705/4)+('Hela matrisen pb 14-16'!C790/4)+('Hela matrisen pb 14-16'!C875/4)+('Hela matrisen pb 14-16'!C960/4) -> 0 | E88: =('Hela matrisen pb 14-16'!D705/4)+('Hela matrisen pb 14-16'!D790/4)+('Hela matrisen pb 14-16'!D875/4)+('Hela matrisen pb 14-16'!D960/4) -> 0 | F88: =('Hela matrisen pb 14-16'!E705/4)+('Hela matrisen pb 14-16'!E790/4)+('Hela matrisen pb 14-16'!E875/4)+('Hela matrisen pb 14-16'!E960/4) -> 6.967575 | G88: =('Hela matrisen pb 14-16'!F705/4)+('Hela matrisen pb 14-16'!F790/4)+('Hela matrisen pb 14-16'!F875/4)+('Hela matrisen pb 14-16'!F960/4) -> 1.9916375 | H88: =('Hela matrisen pb 14-16'!G705/4)+('Hela matrisen pb 14-16'!G790/4)+('Hela matrisen pb 14-16'!G875/4)+('Hela matrisen pb 14-16'!G960/4) -> 10.90795 | I88: =('Hela matrisen pb 14-16'!H705/4)+('Hela matrisen pb 14-16'!H790/4)+('Hela matrisen pb 14-16'!H875/4)+('Hela matrisen pb 14-16'!H960/4) -> 12.14568 | J88: =('Hela matrisen pb 14-16'!I705/4)+('Hela matrisen pb 14-16'!I790/4)+('Hela matrisen pb 14-16'!I875/4)+('Hela matrisen pb 14-16'!I960/4) -> 0 | ... M88: =('Hela matrisen pb 14-16'!L705/4)+('Hela matrisen pb 14-16'!L790/4)+('Hela matrisen pb 14-16'!L875/4)+('Hela matrisen pb 14-16'!L960/4) -> 0 | N88: ='Hela matrisen pb 14-16'!P705/4+'Hela matrisen pb 14-16'!P790/4+'Hela matrisen pb 14-16'!P875/4+'Hela matrisen pb 14-16'!P960/4 -> 0 | O88: ='Hela matrisen pb 14-16'!Q705/4+'Hela matrisen pb 14-16'!Q790/4+'Hela matrisen pb 14-16'!Q875/4+'Hela matrisen pb 14-16'!Q960/4 -> 8.5516375 | P88: ='Hela matrisen pb 14-16'!R705/4+'Hela matrisen pb 14-16'!R790/4+'Hela matrisen pb 14-16'!R875/4+'Hela matrisen pb 14-16'!R960/4 -> 2.9929525 | Q88: ='Hela matrisen pb 14-16'!S705/4+'Hela matrisen pb 14-16'!S790/4+'Hela matrisen pb 14-16'!S875/4+'Hela matrisen pb 14-16'!S960/4 -> 0 | R88: ='Hela matrisen pb 14-16'!T705/4+'Hela matrisen pb 14-16'!T790/4+'Hela matrisen pb 14-16'!T875/4+'Hela matrisen pb 14-16'!T960/4 -> 1.960045 | S88: ='Hela matrisen pb 14-16'!U705/4+'Hela matrisen pb 14-16'!U790/4+'Hela matrisen pb 14-16'!U875/4+'Hela matrisen pb 14-16'!U960/4 -> 0.99204 | T88: ='Hela matrisen pb 14-16'!V705/4+'Hela matrisen pb 14-16'!V790/4+'Hela matrisen pb 14-16'!V875/4+'Hela matrisen pb 14-16'!V960/4 -> 0 | U88: ='Hela matrisen pb 14-16'!W705/4+'Hela matrisen pb 14-16'!W790/4+'Hela matrisen pb 14-16'!W875/4+'Hela matrisen pb 14-16'!W960/4 -> 0.95985 | ... CC88: ='Hela matrisen pb 14-16'!CE705/4+'Hela matrisen pb 14-16'!CE790/4+'Hela matrisen pb 14-16'!CE875/4+'Hela matrisen pb 14-16'!CE960/4 -> 0.9885325 | CD88: ='Hela matrisen pb 14-16'!M960/4+'Hela matrisen pb 14-16'!M875/4+'Hela matrisen pb 14-16'!M790/4+'Hela matrisen pb 14-16'!M705/4 -> 1.9789875 | CE88: ='Hela matrisen pb 14-16'!N960/4+'Hela matrisen pb 14-16'!N875/4+'Hela matrisen pb 14-16'!N790/4+'Hela matrisen pb 14-16'!N705/4 -> 0 | CF88: ='Hela matrisen pb 14-16'!O960/4+'Hela matrisen pb 14-16'!O875/4+'Hela matrisen pb 14-16'!O790/4+'Hela matrisen pb 14-16'!O705/4 -> 0 | CH88: =SUM(C88:CF88) -> 153.64299
B89: 2 | C89: =('Hela matrisen pb 14-16'!B706/4)+('Hela matrisen pb 14-16'!B791/4)+('Hela matrisen pb 14-16'!B876/4)+('Hela matrisen pb 14-16'!B961/4) -> 0 | D89: =('Hela matrisen pb 14-16'!C706/4)+('Hela matrisen pb 14-16'!C791/4)+('Hela matrisen pb 14-16'!C876/4)+('Hela matrisen pb 14-16'!C961/4) -> 0 | E89: =('Hela matrisen pb 14-16'!D706/4)+('Hela matrisen pb 14-16'!D791/4)+('Hela matrisen pb 14-16'!D876/4)+('Hela matrisen pb 14-16'!D961/4) -> 0.95979 | F89: =('Hela matrisen pb 14-16'!E706/4)+('Hela matrisen pb 14-16'!E791/4)+('Hela matrisen pb 14-16'!E876/4)+('Hela matrisen pb 14-16'!E961/4) -> 3.9792325 | G89: =('Hela matrisen pb 14-16'!F706/4)+('Hela matrisen pb 14-16'!F791/4)+('Hela matrisen pb 14-16'!F876/4)+('Hela matrisen pb 14-16'!F961/4) -> 4.9799 | H89: =('Hela matrisen pb 14-16'!G706/4)+('Hela matrisen pb 14-16'!G791/4)+('Hela matrisen pb 14-16'!G876/4)+('Hela matrisen pb 14-16'!G961/4) -> 16.85865 | I89: =('Hela matrisen pb 14-16'!H706/4)+('Hela matrisen pb 14-16'!H791/4)+('Hela matrisen pb 14-16'!H876/4)+('Hela matrisen pb 14-16'!H961/4) -> 4.0480775 | J89: =('Hela matrisen pb 14-16'!I706/4)+('Hela matrisen pb 14-16'!I791/4)+('Hela matrisen pb 14-16'!I876/4)+('Hela matrisen pb 14-16'!I961/4) -> 10.099082 | ... M89: =('Hela matrisen pb 14-16'!L706/4)+('Hela matrisen pb 14-16'!L791/4)+('Hela matrisen pb 14-16'!L876/4)+('Hela matrisen pb 14-16'!L961/4) -> 0 | N89: ='Hela matrisen pb 14-16'!P706/4+'Hela matrisen pb 14-16'!P791/4+'Hela matrisen pb 14-16'!P876/4+'Hela matrisen pb 14-16'!P961/4 -> 0 | O89: ='Hela matrisen pb 14-16'!Q706/4+'Hela matrisen pb 14-16'!Q791/4+'Hela matrisen pb 14-16'!Q876/4+'Hela matrisen pb 14-16'!Q961/4 -> 0 | P89: ='Hela matrisen pb 14-16'!R706/4+'Hela matrisen pb 14-16'!R791/4+'Hela matrisen pb 14-16'!R876/4+'Hela matrisen pb 14-16'!R961/4 -> 2.98815 | Q89: ='Hela matrisen pb 14-16'!S706/4+'Hela matrisen pb 14-16'!S791/4+'Hela matrisen pb 14-16'!S876/4+'Hela matrisen pb 14-16'!S961/4 -> 0.9453775 | R89: ='Hela matrisen pb 14-16'!T706/4+'Hela matrisen pb 14-16'!T791/4+'Hela matrisen pb 14-16'!T876/4+'Hela matrisen pb 14-16'!T961/4 -> 3.91667 | S89: ='Hela matrisen pb 14-16'!U706/4+'Hela matrisen pb 14-16'!U791/4+'Hela matrisen pb 14-16'!U876/4+'Hela matrisen pb 14-16'!U961/4 -> 0 | T89: ='Hela matrisen pb 14-16'!V706/4+'Hela matrisen pb 14-16'!V791/4+'Hela matrisen pb 14-16'!V876/4+'Hela matrisen pb 14-16'!V961/4 -> 0 | U89: ='Hela matrisen pb 14-16'!W706/4+'Hela matrisen pb 14-16'!W791/4+'Hela matrisen pb 14-16'!W876/4+'Hela matrisen pb 14-16'!W961/4 -> 1.9197 | ... CC89: ='Hela matrisen pb 14-16'!CE706/4+'Hela matrisen pb 14-16'!CE791/4+'Hela matrisen pb 14-16'!CE876/4+'Hela matrisen pb 14-16'!CE961/4 -> 2.9762825 | CD89: ='Hela matrisen pb 14-16'!M961/4+'Hela matrisen pb 14-16'!M876/4+'Hela matrisen pb 14-16'!M791/4+'Hela matrisen pb 14-16'!M706/4 -> 1.9824075 | CE89: ='Hela matrisen pb 14-16'!N961/4+'Hela matrisen pb 14-16'!N876/4+'Hela matrisen pb 14-16'!N791/4+'Hela matrisen pb 14-16'!N706/4 -> 0 | CF89: ='Hela matrisen pb 14-16'!O961/4+'Hela matrisen pb 14-16'!O876/4+'Hela matrisen pb 14-16'!O791/4+'Hela matrisen pb 14-16'!O706/4 -> 0 | CH89: =SUM(C89:CF89) -> 195.92307
B90: 3 | C90: =('Hela matrisen pb 14-16'!B707/4)+('Hela matrisen pb 14-16'!B792/4)+('Hela matrisen pb 14-16'!B877/4)+('Hela matrisen pb 14-16'!B962/4) -> 0.955225 | D90: =('Hela matrisen pb 14-16'!C707/4)+('Hela matrisen pb 14-16'!C792/4)+('Hela matrisen pb 14-16'!C877/4)+('Hela matrisen pb 14-16'!C962/4) -> 0 | E90: =('Hela matrisen pb 14-16'!D707/4)+('Hela matrisen pb 14-16'!D792/4)+('Hela matrisen pb 14-16'!D877/4)+('Hela matrisen pb 14-16'!D962/4) -> 0 | F90: =('Hela matrisen pb 14-16'!E707/4)+('Hela matrisen pb 14-16'!E792/4)+('Hela matrisen pb 14-16'!E877/4)+('Hela matrisen pb 14-16'!E962/4) -> 19.90705 | G90: =('Hela matrisen pb 14-16'!F707/4)+('Hela matrisen pb 14-16'!F792/4)+('Hela matrisen pb 14-16'!F877/4)+('Hela matrisen pb 14-16'!F962/4) -> 12.954275 | H90: =('Hela matrisen pb 14-16'!G707/4)+('Hela matrisen pb 14-16'!G792/4)+('Hela matrisen pb 14-16'!G877/4)+('Hela matrisen pb 14-16'!G962/4) -> 16.8604 | I90: =('Hela matrisen pb 14-16'!H707/4)+('Hela matrisen pb 14-16'!H792/4)+('Hela matrisen pb 14-16'!H877/4)+('Hela matrisen pb 14-16'!H962/4) -> 23.847625 | J90: =('Hela matrisen pb 14-16'!I707/4)+('Hela matrisen pb 14-16'!I792/4)+('Hela matrisen pb 14-16'!I877/4)+('Hela matrisen pb 14-16'!I962/4) -> 13.888825 | ... M90: =('Hela matrisen pb 14-16'!L707/4)+('Hela matrisen pb 14-16'!L792/4)+('Hela matrisen pb 14-16'!L877/4)+('Hela matrisen pb 14-16'!L962/4) -> 0 | N90: ='Hela matrisen pb 14-16'!P707/4+'Hela matrisen pb 14-16'!P792/4+'Hela matrisen pb 14-16'!P877/4+'Hela matrisen pb 14-16'!P962/4 -> 0 | O90: ='Hela matrisen pb 14-16'!Q707/4+'Hela matrisen pb 14-16'!Q792/4+'Hela matrisen pb 14-16'!Q877/4+'Hela matrisen pb 14-16'!Q962/4 -> 6.423265 | P90: ='Hela matrisen pb 14-16'!R707/4+'Hela matrisen pb 14-16'!R792/4+'Hela matrisen pb 14-16'!R877/4+'Hela matrisen pb 14-16'!R962/4 -> 2.98881 | Q90: ='Hela matrisen pb 14-16'!S707/4+'Hela matrisen pb 14-16'!S792/4+'Hela matrisen pb 14-16'!S877/4+'Hela matrisen pb 14-16'!S962/4 -> 2.8366275 | R90: ='Hela matrisen pb 14-16'!T707/4+'Hela matrisen pb 14-16'!T792/4+'Hela matrisen pb 14-16'!T877/4+'Hela matrisen pb 14-16'!T962/4 -> 4.908265 | S90: ='Hela matrisen pb 14-16'!U707/4+'Hela matrisen pb 14-16'!U792/4+'Hela matrisen pb 14-16'!U877/4+'Hela matrisen pb 14-16'!U962/4 -> 0 | T90: ='Hela matrisen pb 14-16'!V707/4+'Hela matrisen pb 14-16'!V792/4+'Hela matrisen pb 14-16'!V877/4+'Hela matrisen pb 14-16'!V962/4 -> 0.9601825 | U90: ='Hela matrisen pb 14-16'!W707/4+'Hela matrisen pb 14-16'!W792/4+'Hela matrisen pb 14-16'!W877/4+'Hela matrisen pb 14-16'!W962/4 -> 1.93137 | ... CC90: ='Hela matrisen pb 14-16'!CE707/4+'Hela matrisen pb 14-16'!CE792/4+'Hela matrisen pb 14-16'!CE877/4+'Hela matrisen pb 14-16'!CE962/4 -> 0 | CD90: ='Hela matrisen pb 14-16'!M962/4+'Hela matrisen pb 14-16'!M877/4+'Hela matrisen pb 14-16'!M792/4+'Hela matrisen pb 14-16'!M707/4 -> 0 | CE90: ='Hela matrisen pb 14-16'!N962/4+'Hela matrisen pb 14-16'!N877/4+'Hela matrisen pb 14-16'!N792/4+'Hela matrisen pb 14-16'!N707/4 -> 0 | CF90: ='Hela matrisen pb 14-16'!O962/4+'Hela matrisen pb 14-16'!O877/4+'Hela matrisen pb 14-16'!O792/4+'Hela matrisen pb 14-16'!O707/4 -> 0 | CH90: =SUM(C90:CF90) -> 180.40435
B91: 4 | C91: =('Hela matrisen pb 14-16'!B708/4)+('Hela matrisen pb 14-16'!B793/4)+('Hela matrisen pb 14-16'!B878/4)+('Hela matrisen pb 14-16'!B963/4) -> 2.967345 | D91: =('Hela matrisen pb 14-16'!C708/4)+('Hela matrisen pb 14-16'!C793/4)+('Hela matrisen pb 14-16'!C878/4)+('Hela matrisen pb 14-16'!C963/4) -> 2.96392 | E91: =('Hela matrisen pb 14-16'!D708/4)+('Hela matrisen pb 14-16'!D793/4)+('Hela matrisen pb 14-16'!D878/4)+('Hela matrisen pb 14-16'!D963/4) -> 0.9956325 | F91: =('Hela matrisen pb 14-16'!E708/4)+('Hela matrisen pb 14-16'!E793/4)+('Hela matrisen pb 14-16'!E878/4)+('Hela matrisen pb 14-16'!E963/4) -> 0 | G91: =('Hela matrisen pb 14-16'!F708/4)+('Hela matrisen pb 14-16'!F793/4)+('Hela matrisen pb 14-16'!F878/4)+('Hela matrisen pb 14-16'!F963/4) -> 9.6841475 | H91: =('Hela matrisen pb 14-16'!G708/4)+('Hela matrisen pb 14-16'!G793/4)+('Hela matrisen pb 14-16'!G878/4)+('Hela matrisen pb 14-16'!G963/4) -> 0 | I91: =('Hela matrisen pb 14-16'!H708/4)+('Hela matrisen pb 14-16'!H793/4)+('Hela matrisen pb 14-16'!H878/4)+('Hela matrisen pb 14-16'!H963/4) -> 51.46575 | J91: =('Hela matrisen pb 14-16'!I708/4)+('Hela matrisen pb 14-16'!I793/4)+('Hela matrisen pb 14-16'!I878/4)+('Hela matrisen pb 14-16'!I963/4) -> 58.31555 | ... M91: =('Hela matrisen pb 14-16'!L708/4)+('Hela matrisen pb 14-16'!L793/4)+('Hela matrisen pb 14-16'!L878/4)+('Hela matrisen pb 14-16'!L963/4) -> 7.87845 | N91: ='Hela matrisen pb 14-16'!P708/4+'Hela matrisen pb 14-16'!P793/4+'Hela matrisen pb 14-16'!P878/4+'Hela matrisen pb 14-16'!P963/4 -> 0 | O91: ='Hela matrisen pb 14-16'!Q708/4+'Hela matrisen pb 14-16'!Q793/4+'Hela matrisen pb 14-16'!Q878/4+'Hela matrisen pb 14-16'!Q963/4 -> 5.92623 | P91: ='Hela matrisen pb 14-16'!R708/4+'Hela matrisen pb 14-16'!R793/4+'Hela matrisen pb 14-16'!R878/4+'Hela matrisen pb 14-16'!R963/4 -> 13.035975 | Q91: ='Hela matrisen pb 14-16'!S708/4+'Hela matrisen pb 14-16'!S793/4+'Hela matrisen pb 14-16'!S878/4+'Hela matrisen pb 14-16'!S963/4 -> 4.79292 | R91: ='Hela matrisen pb 14-16'!T708/4+'Hela matrisen pb 14-16'!T793/4+'Hela matrisen pb 14-16'!T878/4+'Hela matrisen pb 14-16'!T963/4 -> 11.067715 | S91: ='Hela matrisen pb 14-16'!U708/4+'Hela matrisen pb 14-16'!U793/4+'Hela matrisen pb 14-16'!U878/4+'Hela matrisen pb 14-16'!U963/4 -> 0 | T91: ='Hela matrisen pb 14-16'!V708/4+'Hela matrisen pb 14-16'!V793/4+'Hela matrisen pb 14-16'!V878/4+'Hela matrisen pb 14-16'!V963/4 -> 0 | U91: ='Hela matrisen pb 14-16'!W708/4+'Hela matrisen pb 14-16'!W793/4+'Hela matrisen pb 14-16'!W878/4+'Hela matrisen pb 14-16'!W963/4 -> 18.11065 | ... CC91: ='Hela matrisen pb 14-16'!CE708/4+'Hela matrisen pb 14-16'!CE793/4+'Hela matrisen pb 14-16'!CE878/4+'Hela matrisen pb 14-16'!CE963/4 -> 3.9309125 | CD91: ='Hela matrisen pb 14-16'!M963/4+'Hela matrisen pb 14-16'!M878/4+'Hela matrisen pb 14-16'!M793/4+'Hela matrisen pb 14-16'!M708/4 -> 0 | CE91: ='Hela matrisen pb 14-16'!N963/4+'Hela matrisen pb 14-16'!N878/4+'Hela matrisen pb 14-16'!N793/4+'Hela matrisen pb 14-16'!N708/4 -> 0 | CF91: ='Hela matrisen pb 14-16'!O963/4+'Hela matrisen pb 14-16'!O878/4+'Hela matrisen pb 14-16'!O793/4+'Hela matrisen pb 14-16'!O708/4 -> 0 | CH91: =SUM(C91:CF91) -> 372.76614
B92: 5 | C92: =('Hela matrisen pb 14-16'!B709/4)+('Hela matrisen pb 14-16'!B794/4)+('Hela matrisen pb 14-16'!B879/4)+('Hela matrisen pb 14-16'!B964/4) -> 0 | D92: =('Hela matrisen pb 14-16'!C709/4)+('Hela matrisen pb 14-16'!C794/4)+('Hela matrisen pb 14-16'!C879/4)+('Hela matrisen pb 14-16'!C964/4) -> 0.9886175 | E92: =('Hela matrisen pb 14-16'!D709/4)+('Hela matrisen pb 14-16'!D794/4)+('Hela matrisen pb 14-16'!D879/4)+('Hela matrisen pb 14-16'!D964/4) -> 1.9937275 | F92: =('Hela matrisen pb 14-16'!E709/4)+('Hela matrisen pb 14-16'!E794/4)+('Hela matrisen pb 14-16'!E879/4)+('Hela matrisen pb 14-16'!E964/4) -> 6.85984 | G92: =('Hela matrisen pb 14-16'!F709/4)+('Hela matrisen pb 14-16'!F794/4)+('Hela matrisen pb 14-16'!F879/4)+('Hela matrisen pb 14-16'!F964/4) -> 0 | H92: =('Hela matrisen pb 14-16'!G709/4)+('Hela matrisen pb 14-16'!G794/4)+('Hela matrisen pb 14-16'!G879/4)+('Hela matrisen pb 14-16'!G964/4) -> 3.0548625 | I92: =('Hela matrisen pb 14-16'!H709/4)+('Hela matrisen pb 14-16'!H794/4)+('Hela matrisen pb 14-16'!H879/4)+('Hela matrisen pb 14-16'!H964/4) -> 25.3719 | J92: =('Hela matrisen pb 14-16'!I709/4)+('Hela matrisen pb 14-16'!I794/4)+('Hela matrisen pb 14-16'!I879/4)+('Hela matrisen pb 14-16'!I964/4) -> 9.105595 | ... M92: =('Hela matrisen pb 14-16'!L709/4)+('Hela matrisen pb 14-16'!L794/4)+('Hela matrisen pb 14-16'!L879/4)+('Hela matrisen pb 14-16'!L964/4) -> 0 | N92: ='Hela matrisen pb 14-16'!P709/4+'Hela matrisen pb 14-16'!P794/4+'Hela matrisen pb 14-16'!P879/4+'Hela matrisen pb 14-16'!P964/4 -> 0 | O92: ='Hela matrisen pb 14-16'!Q709/4+'Hela matrisen pb 14-16'!Q794/4+'Hela matrisen pb 14-16'!Q879/4+'Hela matrisen pb 14-16'!Q964/4 -> 0 | P92: ='Hela matrisen pb 14-16'!R709/4+'Hela matrisen pb 14-16'!R794/4+'Hela matrisen pb 14-16'!R879/4+'Hela matrisen pb 14-16'!R964/4 -> 5.03369 | Q92: ='Hela matrisen pb 14-16'!S709/4+'Hela matrisen pb 14-16'!S794/4+'Hela matrisen pb 14-16'!S879/4+'Hela matrisen pb 14-16'!S964/4 -> 7.05493 | R92: ='Hela matrisen pb 14-16'!T709/4+'Hela matrisen pb 14-16'!T794/4+'Hela matrisen pb 14-16'!T879/4+'Hela matrisen pb 14-16'!T964/4 -> 11.13451 | S92: ='Hela matrisen pb 14-16'!U709/4+'Hela matrisen pb 14-16'!U794/4+'Hela matrisen pb 14-16'!U879/4+'Hela matrisen pb 14-16'!U964/4 -> 0 | T92: ='Hela matrisen pb 14-16'!V709/4+'Hela matrisen pb 14-16'!V794/4+'Hela matrisen pb 14-16'!V879/4+'Hela matrisen pb 14-16'!V964/4 -> 1.0125875 | U92: ='Hela matrisen pb 14-16'!W709/4+'Hela matrisen pb 14-16'!W794/4+'Hela matrisen pb 14-16'!W879/4+'Hela matrisen pb 14-16'!W964/4 -> 8.09674 | ... CC92: ='Hela matrisen pb 14-16'!CE709/4+'Hela matrisen pb 14-16'!CE794/4+'Hela matrisen pb 14-16'!CE879/4+'Hela matrisen pb 14-16'!CE964/4 -> 0.9886875 | CD92: ='Hela matrisen pb 14-16'!M964/4+'Hela matrisen pb 14-16'!M879/4+'Hela matrisen pb 14-16'!M794/4+'Hela matrisen pb 14-16'!M709/4 -> 0.9878225 | CE92: ='Hela matrisen pb 14-16'!N964/4+'Hela matrisen pb 14-16'!N879/4+'Hela matrisen pb 14-16'!N794/4+'Hela matrisen pb 14-16'!N709/4 -> 0 | CF92: ='Hela matrisen pb 14-16'!O964/4+'Hela matrisen pb 14-16'!O879/4+'Hela matrisen pb 14-16'!O794/4+'Hela matrisen pb 14-16'!O709/4 -> 0 | CH92: =SUM(C92:CF92) -> 162.89667
B93: 6 | C93: =('Hela matrisen pb 14-16'!B710/4)+('Hela matrisen pb 14-16'!B795/4)+('Hela matrisen pb 14-16'!B880/4)+('Hela matrisen pb 14-16'!B965/4) -> 5.9298 | D93: =('Hela matrisen pb 14-16'!C710/4)+('Hela matrisen pb 14-16'!C795/4)+('Hela matrisen pb 14-16'!C880/4)+('Hela matrisen pb 14-16'!C965/4) -> 4.9417925 | E93: =('Hela matrisen pb 14-16'!D710/4)+('Hela matrisen pb 14-16'!D795/4)+('Hela matrisen pb 14-16'!D880/4)+('Hela matrisen pb 14-16'!D965/4) -> 5.95847 | F93: =('Hela matrisen pb 14-16'!E710/4)+('Hela matrisen pb 14-16'!E795/4)+('Hela matrisen pb 14-16'!E880/4)+('Hela matrisen pb 14-16'!E965/4) -> 20 | G93: =('Hela matrisen pb 14-16'!F710/4)+('Hela matrisen pb 14-16'!F795/4)+('Hela matrisen pb 14-16'!F880/4)+('Hela matrisen pb 14-16'!F965/4) -> 20 | H93: =('Hela matrisen pb 14-16'!G710/4)+('Hela matrisen pb 14-16'!G795/4)+('Hela matrisen pb 14-16'!G880/4)+('Hela matrisen pb 14-16'!G965/4) -> 0 | I93: =('Hela matrisen pb 14-16'!H710/4)+('Hela matrisen pb 14-16'!H795/4)+('Hela matrisen pb 14-16'!H880/4)+('Hela matrisen pb 14-16'!H965/4) -> 362.0135 | J93: =('Hela matrisen pb 14-16'!I710/4)+('Hela matrisen pb 14-16'!I795/4)+('Hela matrisen pb 14-16'!I880/4)+('Hela matrisen pb 14-16'!I965/4) -> 124.21 | ... M93: =('Hela matrisen pb 14-16'!L710/4)+('Hela matrisen pb 14-16'!L795/4)+('Hela matrisen pb 14-16'!L880/4)+('Hela matrisen pb 14-16'!L965/4) -> 0 | N93: ='Hela matrisen pb 14-16'!P710/4+'Hela matrisen pb 14-16'!P795/4+'Hela matrisen pb 14-16'!P880/4+'Hela matrisen pb 14-16'!P965/4 -> 5.9909525 | O93: ='Hela matrisen pb 14-16'!Q710/4+'Hela matrisen pb 14-16'!Q795/4+'Hela matrisen pb 14-16'!Q880/4+'Hela matrisen pb 14-16'!Q965/4 -> 6.02431 | P93: ='Hela matrisen pb 14-16'!R710/4+'Hela matrisen pb 14-16'!R795/4+'Hela matrisen pb 14-16'!R880/4+'Hela matrisen pb 14-16'!R965/4 -> 13.01794 | Q93: ='Hela matrisen pb 14-16'!S710/4+'Hela matrisen pb 14-16'!S795/4+'Hela matrisen pb 14-16'!S880/4+'Hela matrisen pb 14-16'!S965/4 -> 15.8738 | R93: ='Hela matrisen pb 14-16'!T710/4+'Hela matrisen pb 14-16'!T795/4+'Hela matrisen pb 14-16'!T880/4+'Hela matrisen pb 14-16'!T965/4 -> 12.0042 | S93: ='Hela matrisen pb 14-16'!U710/4+'Hela matrisen pb 14-16'!U795/4+'Hela matrisen pb 14-16'!U880/4+'Hela matrisen pb 14-16'!U965/4 -> 4.0181125 | T93: ='Hela matrisen pb 14-16'!V710/4+'Hela matrisen pb 14-16'!V795/4+'Hela matrisen pb 14-16'!V880/4+'Hela matrisen pb 14-16'!V965/4 -> 2.00205 | U93: ='Hela matrisen pb 14-16'!W710/4+'Hela matrisen pb 14-16'!W795/4+'Hela matrisen pb 14-16'!W880/4+'Hela matrisen pb 14-16'!W965/4 -> 13.003875 | ... CC93: ='Hela matrisen pb 14-16'!CE710/4+'Hela matrisen pb 14-16'!CE795/4+'Hela matrisen pb 14-16'!CE880/4+'Hela matrisen pb 14-16'!CE965/4 -> 4.038005 | CD93: ='Hela matrisen pb 14-16'!M965/4+'Hela matrisen pb 14-16'!M880/4+'Hela matrisen pb 14-16'!M795/4+'Hela matrisen pb 14-16'!M710/4 -> 0 | CE93: ='Hela matrisen pb 14-16'!N965/4+'Hela matrisen pb 14-16'!N880/4+'Hela matrisen pb 14-16'!N795/4+'Hela matrisen pb 14-16'!N710/4 -> 0 | CF93: ='Hela matrisen pb 14-16'!O965/4+'Hela matrisen pb 14-16'!O880/4+'Hela matrisen pb 14-16'!O795/4+'Hela matrisen pb 14-16'!O710/4 -> 0 | CH93: =SUM(C93:CF93) -> 1181.2654
B94: 7 | C94: =('Hela matrisen pb 14-16'!B711/4)+('Hela matrisen pb 14-16'!B796/4)+('Hela matrisen pb 14-16'!B881/4)+('Hela matrisen pb 14-16'!B966/4) -> 0.98316 | D94: =('Hela matrisen pb 14-16'!C711/4)+('Hela matrisen pb 14-16'!C796/4)+('Hela matrisen pb 14-16'!C881/4)+('Hela matrisen pb 14-16'!C966/4) -> 0.9816225 | E94: =('Hela matrisen pb 14-16'!D711/4)+('Hela matrisen pb 14-16'!D796/4)+('Hela matrisen pb 14-16'!D881/4)+('Hela matrisen pb 14-16'!D966/4) -> 5.871895 | F94: =('Hela matrisen pb 14-16'!E711/4)+('Hela matrisen pb 14-16'!E796/4)+('Hela matrisen pb 14-16'!E881/4)+('Hela matrisen pb 14-16'!E966/4) -> 39.07035 | G94: =('Hela matrisen pb 14-16'!F711/4)+('Hela matrisen pb 14-16'!F796/4)+('Hela matrisen pb 14-16'!F881/4)+('Hela matrisen pb 14-16'!F966/4) -> 13.032575 | H94: =('Hela matrisen pb 14-16'!G711/4)+('Hela matrisen pb 14-16'!G796/4)+('Hela matrisen pb 14-16'!G881/4)+('Hela matrisen pb 14-16'!G966/4) -> 528.86575 | I94: =('Hela matrisen pb 14-16'!H711/4)+('Hela matrisen pb 14-16'!H796/4)+('Hela matrisen pb 14-16'!H881/4)+('Hela matrisen pb 14-16'!H966/4) -> 0 | J94: =('Hela matrisen pb 14-16'!I711/4)+('Hela matrisen pb 14-16'!I796/4)+('Hela matrisen pb 14-16'!I881/4)+('Hela matrisen pb 14-16'!I966/4) -> 0 | ... M94: =('Hela matrisen pb 14-16'!L711/4)+('Hela matrisen pb 14-16'!L796/4)+('Hela matrisen pb 14-16'!L881/4)+('Hela matrisen pb 14-16'!L966/4) -> 0 | N94: ='Hela matrisen pb 14-16'!P711/4+'Hela matrisen pb 14-16'!P796/4+'Hela matrisen pb 14-16'!P881/4+'Hela matrisen pb 14-16'!P966/4 -> 0 | O94: ='Hela matrisen pb 14-16'!Q711/4+'Hela matrisen pb 14-16'!Q796/4+'Hela matrisen pb 14-16'!Q881/4+'Hela matrisen pb 14-16'!Q966/4 -> 4.0324175 | P94: ='Hela matrisen pb 14-16'!R711/4+'Hela matrisen pb 14-16'!R796/4+'Hela matrisen pb 14-16'!R881/4+'Hela matrisen pb 14-16'!R966/4 -> 7.774125 | Q94: ='Hela matrisen pb 14-16'!S711/4+'Hela matrisen pb 14-16'!S796/4+'Hela matrisen pb 14-16'!S881/4+'Hela matrisen pb 14-16'!S966/4 -> 5.8742125 | R94: ='Hela matrisen pb 14-16'!T711/4+'Hela matrisen pb 14-16'!T796/4+'Hela matrisen pb 14-16'!T881/4+'Hela matrisen pb 14-16'!T966/4 -> 7.8740825 | S94: ='Hela matrisen pb 14-16'!U711/4+'Hela matrisen pb 14-16'!U796/4+'Hela matrisen pb 14-16'!U881/4+'Hela matrisen pb 14-16'!U966/4 -> 2.947895 | T94: ='Hela matrisen pb 14-16'!V711/4+'Hela matrisen pb 14-16'!V796/4+'Hela matrisen pb 14-16'!V881/4+'Hela matrisen pb 14-16'!V966/4 -> 0 | U94: ='Hela matrisen pb 14-16'!W711/4+'Hela matrisen pb 14-16'!W796/4+'Hela matrisen pb 14-16'!W881/4+'Hela matrisen pb 14-16'!W966/4 -> 12.8497 | ... CC94: ='Hela matrisen pb 14-16'!CE711/4+'Hela matrisen pb 14-16'!CE796/4+'Hela matrisen pb 14-16'!CE881/4+'Hela matrisen pb 14-16'!CE966/4 -> 7.9278075 | CD94: ='Hela matrisen pb 14-16'!M966/4+'Hela matrisen pb 14-16'!M881/4+'Hela matrisen pb 14-16'!M796/4+'Hela matrisen pb 14-16'!M711/4 -> 0 | CE94: ='Hela matrisen pb 14-16'!N966/4+'Hela matrisen pb 14-16'!N881/4+'Hela matrisen pb 14-16'!N796/4+'Hela matrisen pb 14-16'!N711/4 -> 0 | CF94: ='Hela matrisen pb 14-16'!O966/4+'Hela matrisen pb 14-16'!O881/4+'Hela matrisen pb 14-16'!O796/4+'Hela matrisen pb 14-16'!O711/4 -> 0 | CH94: =SUM(C94:CF94) -> 1349.0734
B95: 8 | C95: =('Hela matrisen pb 14-16'!B712/4)+('Hela matrisen pb 14-16'!B797/4)+('Hela matrisen pb 14-16'!B882/4)+('Hela matrisen pb 14-16'!B967/4) -> 3.9343 | D95: =('Hela matrisen pb 14-16'!C712/4)+('Hela matrisen pb 14-16'!C797/4)+('Hela matrisen pb 14-16'!C882/4)+('Hela matrisen pb 14-16'!C967/4) -> 0 | E95: =('Hela matrisen pb 14-16'!D712/4)+('Hela matrisen pb 14-16'!D797/4)+('Hela matrisen pb 14-16'!D882/4)+('Hela matrisen pb 14-16'!D967/4) -> 5.878605 | F95: =('Hela matrisen pb 14-16'!E712/4)+('Hela matrisen pb 14-16'!E797/4)+('Hela matrisen pb 14-16'!E882/4)+('Hela matrisen pb 14-16'!E967/4) -> 135.4195 | G95: =('Hela matrisen pb 14-16'!F712/4)+('Hela matrisen pb 14-16'!F797/4)+('Hela matrisen pb 14-16'!F882/4)+('Hela matrisen pb 14-16'!F967/4) -> 24.097675 | H95: =('Hela matrisen pb 14-16'!G712/4)+('Hela matrisen pb 14-16'!G797/4)+('Hela matrisen pb 14-16'!G882/4)+('Hela matrisen pb 14-16'!G967/4) -> 159.01725 | I95: =('Hela matrisen pb 14-16'!H712/4)+('Hela matrisen pb 14-16'!H797/4)+('Hela matrisen pb 14-16'!H882/4)+('Hela matrisen pb 14-16'!H967/4) -> 0 | J95: =('Hela matrisen pb 14-16'!I712/4)+('Hela matrisen pb 14-16'!I797/4)+('Hela matrisen pb 14-16'!I882/4)+('Hela matrisen pb 14-16'!I967/4) -> 0 | ... M95: =('Hela matrisen pb 14-16'!L712/4)+('Hela matrisen pb 14-16'!L797/4)+('Hela matrisen pb 14-16'!L882/4)+('Hela matrisen pb 14-16'!L967/4) -> 0 | N95: ='Hela matrisen pb 14-16'!P712/4+'Hela matrisen pb 14-16'!P797/4+'Hela matrisen pb 14-16'!P882/4+'Hela matrisen pb 14-16'!P967/4 -> 0.9642225 | O95: ='Hela matrisen pb 14-16'!Q712/4+'Hela matrisen pb 14-16'!Q797/4+'Hela matrisen pb 14-16'!Q882/4+'Hela matrisen pb 14-16'!Q967/4 -> 2.018415 | P95: ='Hela matrisen pb 14-16'!R712/4+'Hela matrisen pb 14-16'!R797/4+'Hela matrisen pb 14-16'!R882/4+'Hela matrisen pb 14-16'!R967/4 -> 7.793525 | Q95: ='Hela matrisen pb 14-16'!S712/4+'Hela matrisen pb 14-16'!S797/4+'Hela matrisen pb 14-16'!S882/4+'Hela matrisen pb 14-16'!S967/4 -> 8.77445 | R95: ='Hela matrisen pb 14-16'!T712/4+'Hela matrisen pb 14-16'!T797/4+'Hela matrisen pb 14-16'!T882/4+'Hela matrisen pb 14-16'!T967/4 -> 9.854875 | S95: ='Hela matrisen pb 14-16'!U712/4+'Hela matrisen pb 14-16'!U797/4+'Hela matrisen pb 14-16'!U882/4+'Hela matrisen pb 14-16'!U967/4 -> 0 | T95: ='Hela matrisen pb 14-16'!V712/4+'Hela matrisen pb 14-16'!V797/4+'Hela matrisen pb 14-16'!V882/4+'Hela matrisen pb 14-16'!V967/4 -> 0 | U95: ='Hela matrisen pb 14-16'!W712/4+'Hela matrisen pb 14-16'!W797/4+'Hela matrisen pb 14-16'!W882/4+'Hela matrisen pb 14-16'!W967/4 -> 13.852 | ... CC95: ='Hela matrisen pb 14-16'!CE712/4+'Hela matrisen pb 14-16'!CE797/4+'Hela matrisen pb 14-16'!CE882/4+'Hela matrisen pb 14-16'!CE967/4 -> 0 | CD95: ='Hela matrisen pb 14-16'!M967/4+'Hela matrisen pb 14-16'!M882/4+'Hela matrisen pb 14-16'!M797/4+'Hela matrisen pb 14-16'!M712/4 -> 0.985835 | CE95: ='Hela matrisen pb 14-16'!N967/4+'Hela matrisen pb 14-16'!N882/4+'Hela matrisen pb 14-16'!N797/4+'Hela matrisen pb 14-16'!N712/4 -> 0 | CF95: ='Hela matrisen pb 14-16'!O967/4+'Hela matrisen pb 14-16'!O882/4+'Hela matrisen pb 14-16'!O797/4+'Hela matrisen pb 14-16'!O712/4 -> 0 | CH95: =SUM(C95:CF95) -> 612.69177
